Workbook
Name A: 'Mẫu phiếu thông báo'!$A$3
Name MaKH: Data!#REF!
Name MaKH: 'In phieu thu'!#REF!

Sheet In phieu thu
A1: Phiếu thu tháng: | C1: 12 | D1: năm | E1: 2020
A2: Từ số: | C2: 206
A3: Đến số: | C3: 206 | E3: 1
C6: 206 | R6: 0
B10: Hướng dẫn để thằng ngu nhất quả đất cũng làm được:
B11: - Chọn sheet "Nhập dữ liệu", Bấm vào nút "LAM THANG MOI"
B12: - Sau khi bấm vào LAM THANG MOI cậu/mợ nào làm nhớ Save as ra file khác với tên file có dạng "Phieu dien Txx nam xxxx" không sau này muốn tra lại thì vỡ mồm con chồn
B13: - Kiểm tra thông tin của hộ tiêu thụ (Tên và địa chỉ)
B14: - Kiểm tra số kw được bao cấp và hệ số nhân
B15: - Chọn số phiếu thu cần in (P2 và P3) Enter
B16: - Click vào IN PHIẾU THU
B17: - Phiếu thông báo điện tiêu thụ được format trên khổ giấy A5, in luôn, không phải xoắn
B18: - Phiếu thông báo được lưu tại sheet "Phiếu thông báo"
B19: - In bảng tổng hợp tại sheet "Bảng tổng hợp"
B20: Chú ý:
B21: - Biết thì phá, không biết từ từ hãy phá, chỉ thao tác ở sheet "Nhập dữ liệu"

Sheet Bảng kê
A1: BẢNG TỔNG HỢP HỘ TIÊU THỤ ĐIỆN THÁNG 3 NĂM 2025
A3: STT | B3: Hộ tiêu thụ điện | C3: Đơn vị chủ quản | D3: Địa chỉ hộ tiêu thụ điện | E3: Điện thoại hộ tiêu thụ điện | F3: Đại diện hộ tiêu thụ | G3: Điện thoại người đại diện | H3: Nhà/ Tòa nhà | I3: T | J3: Số công tơ | K3: Loại công tơ | L3: Vị trí đặt công tơ | M3: Trạm biến áp | N3: Trang | O3: Chỉ số mới | P3: Chỉ số cũ | Q3: Hệ số nhân | R3: Tổng điện năng tiêu thụ | S3: Bao cấp | T3: Điện năng tiêu thụ phải trả | U3: Đơn giá trả công ty Điện lực HBT và hao tổn đường dây | V3: Thành tiền | W3: Người thực hiện
A4: -1 | B4: -2 | C4: -3 | D4: -4 | E4: -5 | F4: -6 | G4: -7 | H4: -8 | I4: -9 | J4: -10 | K4: -11 | L4: -12 | M4: -13 | N4: -14 | O4: -15 | P4: -15 | Q4: -17 | R4: -18 | S4: -19 | T4: -20 | U4: -21 | V4: -22 | W4: -23
A5: 2 | B5: Kiot Trịnh Thị Thu Trang | C5: HĐKT | D5: Lô 13B KĐB - SVĐ | E5: 0359933033 | F5: Trịnh Thị Thu Trang | G5: 0986675792 | H5: SVĐ | J5: 3206 | K5: 1 pha | L5: KĐ B- SVĐ | M5: VVL | N5: 1 | O5: 5788 | P5: 5725 | Q5: 1 | R5: =(O5-P5)*Q5 -> 63 | S5: 0 | T5: =IF((R5-S5)>0,(R5-S5),0) -> 63 | U5: 4169 | V5: =T5*U5 -> 262647 | W5: Sơn
A6: 4 | B6: Chị Khánh - Dịch vụ SVĐ | C6: HĐKT | D6: Lô 14, 15 KĐB - SVĐ | F6: Chị Khánh | G6: 0975297996 | H6: SVĐ | J6: 5440 | K6: 3 pha | L6: KĐ B- SVĐ | M6: VVL | N6: 2 | O6: 135902 | P6: 134676 | Q6: 1 | R6: =(O6-P6)*Q6 -> 1226 | S6: 0 | T6: =IF((R6-S6)>0,(R6-S6),0) -> 1226 | U6: 4169 | V6: =T6*U6 -> 5111194 | W6: Sơn
A7: 5 | B7: Kiot Trịnh Thị Thu Trang | C7: HĐKT | D7: Lô 7-13A KĐB - SVĐ | E7: 0359933033 | F7: Trịnh Thị Thu Trang | G7: 0986675792 | H7: SVĐ | J7: 4220 | K7: 3 pha | L7: KĐ B- SVĐ | M7: VVL | N7: 3 | O7: 177823 | P7: 175018 | Q7: 1 | R7: =(O7-P7)*Q7 -> 2805 | S7: 0 | T7: =IF((R7-S7)>0,(R7-S7),0) -> 2805 | U7: 4169 | V7: =T7*U7 -> 11694045 | W7: Sơn
A8: 6 | B8: Kiot nướng KĐ B. Trang | C8: HĐKT | D8: Lô 456 KĐ B SVĐ | E8: 0359933033 | F8: Trịnh Thị Thu Trang | G8: 0986675792 | H8: SVĐ | J8: 9482 | K8: 3 pha | L8: KĐ B- SVĐ | M8: VVL | N8: 3 | O8: 25168 | P8: 24016 | Q8: 1 | R8: =(O8-P8)*Q8 -> 1152 | S8: 0 | T8: =IF((R8-S8)>0,(R8-S8),0) -> 1152 | U8: 4169 | V8: =T8*U8 -> 4802688 | W8: Sơn
A9: 7 | B9: Quán ăn uống giải khát c.Ly | C9: HĐKT | D9: Tầng 1 Số 10 TQB | F9: Nguyễn Hương Ly | G9: 0945656446 | H9: Số 10 TQB | J9: 5089 | K9: 3 pha | L9: Tủ tổng T1 | M9: B1 | N9: 4 | O9: 430404 | P9: 428007 | Q9: 1 | R9: =(O9-P9)*Q9 -> 2397 | S9: 0 | T9: =IF((R9-S9)>0,(R9-S9),0) -> 2397 | U9: 4169 | V9: =T9*U9 -> 9993093 | W9: Đông
A10: 8 | B10: Phòng giao dịch Trung tâm VNPT Hà Nội | C10: HĐKT | D10: Tầng 1 Số 10 TQB | E10: 38240993 | F10: Lê Ngọc Anh | G10: 0918764073 | H10: Số 10 TQB | J10: 2174 | K10: 1 pha | L10: Tầng 1 TTPV | M10: B1 | N10: 5 | O10: 81088 | P10: 80845 | Q10: 1 | R10: =(O10-P10)*Q10 -> 243 | S10: 0 | T10: =IF((R10-S10)>0,(R10-S10),0) -> 243 | U10: 4169 | V10: =T10*U10 -> 1013067 | W10: Đông
A11: 9 | B11: CLB Bi-a Phú Kỳ T2 | C11: HĐKT | D11: Tầng 2 Số 10 TQB | F11: Lan Anh | G11: 0912894948 | H11: Số 10 TQB | J11: 1738 | K11: 1 pha | L11: KTĐ T1 | M11: B1 | N11: 6 | O11: 97163 | P11: 95380 | Q11: 1 | R11: =(O11-P11)*Q11 -> 1783 | S11: 0 | T11: =IF((R11-S11)>0,(R11-S11),0) -> 1783 | U11: 4169 | V11: =T11*U11 -> 7433327 | W11: Đông
A12: 10 | B12: CLB Bi-a Yến T2 | C12: HĐKT | D12: Tầng 2 Số 10 TQB | F12: Trịnh Thị Yến | G12: 0888261868 | H12: Số 10 TQB | J12: 2709 | K12: 3 pha | L12: KTĐ T1 | M12: B1 | N12: 6 | O12: 15512 | P12: 14382 | Q12: 1 | R12: =(O12-P12)*Q12 -> 1130 | S12: 0 | T12: =IF((R12-S12)>0,(R12-S12),0) -> 1130 | U12: 4169 | V12: =T12*U12 -> 4710970 | W12: Đông
A13: 11 | B13: Siêu thị Nam Phong | C13: HĐKT | D13: Tầng 1 Số 10 TQB | F13: Nguyễn Triều Phong | G13: 0944289288 | H13: Số 10 TQB | J13: 3448 | K13: 3 pha | L13: Tầng 1 TTPV | M13: B1 | N13: 6 | O13: 473309 | P13: 470248 | Q13: 1 | R13: =(O13-P13)*Q13 -> 3061 | S13: 0 | T13: =IF((R13-S13)>0,(R13-S13),0) -> 3061 | U13: 4169 | V13: =T13*U13 -> 12761309 | W13: Đông
A14: 12 | B14: Lớp học thầy Chung T3 | C14: HĐKT | D14: Tầng 3 Số 10 TQB | F14: Nguyễn Thị Đào | G14: 0972261616 | H14: Số 10 TQB | J14: 2028 | K14: 1 pha | L14: Tầng 3 TTPV | M14: B1 | N14: 7 | O14: 12320 | P14: 11764 | Q14: 1 | R14: =(O14-P14)*Q14 -> 556 | S14: 0 | T14: =IF((R14-S14)>0,(R14-S14),0) -> 556 | U14: 4169 | V14: =T14*U14 -> 2317964 | W14: Đông
A15: 13 | B15: Văn phòng thầy Chung | C15: HĐKT | D15: Tầng 4 Số 10 TQB | E15: 0972261616 | F15: Nguyễn Thị Đào | G15: 0972261616 | H15: Số 10 TQB | J15: 9307 | K15: 3 pha | L15: Tầng 1 TTPV | M15: B1 | N15: 8 | O15: 100668 | P15: 99309 | Q15: 1 | R15: =(O15-P15)*Q15 -> 1359 | S15: 0 | T15: =IF((R15-S15)>0,(R15-S15),0) -> 1359 | U15: 4169 | V15: =T15*U15 -> 5665671 | W15: Đông
A16: 14 | B16: Vật lý siêu nhẩm tầng 3 | C16: HĐKT | D16: Tầng 3 Số 10 TQB | F16: Trần Quang Quý | G16: 0977340326 | H16: Số 10 TQB | J16: 8259 | K16: 1 pha | L16: Tầng 1 | M16: B1 | N16: 8 | O16: 7904 | P16: 7303 | Q16: 1 | R16: =(O16-P16)*Q16 -> 601 | S16: 0 | T16: =IF((R16-S16)>0,(R16-S16),0) -> 601 | U16: 4169 | V16: =T16*U16 -> 2505569 | W16: Đông
A17: 15 | B17: CLB Bi-a coffee tầng 3 | C17: HĐKT | D17: Tầng 3 Số 10 TQB | F17: Thu Hương | G17: 0912567686 | H17: Số 10 TQB | J17: 7671 | K17: 3 pha | L17: Tầng 3 | M17: B1 | N17: 9 | O17: 336037 | P17: 334264 | Q17: 1 | R17: =(O17-P17)*Q17 -> 1773 | S17: 0 | T17: =IF((R17-S17)>0,(R17-S17),0) -> 1773 | U17: 4169 | V17: =T17*U17 -> 7391637 | W17: Đông
A18: 16 | B18: Công ty CPXD Hoàng Hà | C18: HĐKT | D18: Dịch vụ trông xe - 10A TQB | E18: 0903251444 | F18: Chị Hoa | G18: 0903251444 | H18: Số 10 TQB | J18: 60755 | K18: 3 pha | L18: 10A TQB | M18: B1 | N18: 9 | O18: 189466 | P18: 186518 | Q18: 1 | R18: =(O18-P18)*Q18 -> 2948 | S18: 0 | T18: =IF((R18-S18)>0,(R18-S18),0) -> 2948 | U18: 4169 | V18: =T18*U18 -> 12290212 | W18: Đông
A19: 17 | B19: Kiot chị Hiền cổng TT Y tế | C19: HĐKT | D19: Số 5 TQB | E19: 0978819260 | F19: Chị Hiền | G19: 0915023999 | J19: 1778 | K19: 1 pha | L19: Số 5 TQB | M19: KTX | N19: 10 | O19: 86812 | P19: 86110 | Q19: 1 | R19: =(O19-P19)*Q19 -> 702 | S19: 0 | T19: =IF((R19-S19)>0,(R19-S19),0) -> 702 | U19: 4169 | V19: =T19*U19 -> 2926638 | W19: Đông
A20: 21 | B20: Công ty CP Công nghệ cao GENE Việt | C20: Công ty CP Công nghệ cao GENE Việt | D20: Tầng 11 nhà B1 | E20: 0243.7379150 | F20: Lương Thị Minh Ngoc | G20: 0977295439 | H20: B1 | J20: 1478 | K20: 3 pha | L20: KTĐ T11 | M20: B1 | N20: 11 | O20: 299403 | P20: 298845 | Q20: 1 | R20: =(O20-P20)*Q20 -> 558 | S20: 0 | T20: =IF((R20-S20)>0,(R20-S20),0) -> 558 | U20: 4169 | V20: =T20*U20 -> 2326302 | W20: Sơn
A21: 22 | B21: Cửa hàng Highlands BK | C21: Công ty CP dịch vụ và cà phê Cao Nguyên | D21: Cửa hàng Highlands B1-TĐN | E21: 0988051418 | F21: Trịnh Thị My | G21: 0948742589 | H21: B1 | J21: 90445 | K21: 3 pha | L21: KTĐ T1 | M21: B1 | N21: 12 | O21: 466332 | P21: 461613 | Q21: 1 | R21: =(O21-P21)*Q21 -> 4719 | S21: 0 | T21: =IF((R21-S21)>0,(R21-S21),0) -> 4719 | U21: 4169 | V21: =T21*U21 -> 19673511 | W21: Sơn
A22: 23 | B22: Nhà sách ADC Trần Đại Nghĩa | D22: Nhà sách B1- TĐN | F22: A Quang | G22: 0975744134 | J22: 3307 | K22: 3 pha | L22: KTĐ T1 | M22: B1 | N22: 12 | O22: 66481 | P22: 64127 | Q22: 1 | R22: =(O22-P22)*Q22 -> 2354 | S22: 0 | T22: =IF((R22-S22)>0,(R22-S22),0) -> 2354 | U22: 4169 | V22: =T22*U22 -> 9813826 | W22: Sơn
A23: 24 | B23: Khoa Việt Nam học và Tiếng việt (t thụ) | C23: Trường ĐH KHXH và NV | D23: B7 BIS phố TĐN | E23: 38694323 | F23: Lê Thị Thanh Tâm | G23: 0982886906 | H23: B7 BIS | J23: 9094, 4383 | K23: 3 pha | L23: KTĐ T1 | M23: ĐCĐT | N23: 13 | O23: 1405 | P23: 0 | Q23: 1 | R23: =(O23-P23)*Q23 -> 1405 | S23: 0 | T23: =IF((R23-S23)>0,(R23-S23),0) -> 1405 | U23: 4169 | V23: =T23*U23 -> 5857445 | W23: Đông
A24: 25 | B24: Nhà ăn T3-D2A | C24: Nhà ăn T3-D2A | D24: Tầng 3 - D2A | H24: D2A | J24: 9045 | K24: 3 pha | L24: Tầng 1 D2A | M24: TVĐT | N24: 14 | O24: 195372 | P24: 193672 | Q24: 1 | R24: =(O24-P24)*Q24 -> 1700 | S24: 0 | T24: =IF((R24-S24)>0,(R24-S24),0) -> 1700 | U24: 4169 | V24: =T24*U24 -> 7087300 | W24: Biên
A25: 28 | B25: Tạ Thanh Hằng - Photocopy | C25: HĐKT | D25: Nhà D6 | F25: Tạ Thanh Hằng | G25: 0819906149 | H25: D6 | J25: 3842 | K25: 1 pha | L25: T1 D6 | M25: TVĐT | N25: 15 | O25: 44919 | P25: 44583 | Q25: 1 | R25: =(O25-P25)*Q25 -> 336 | S25: 0 | T25: =IF((R25-S25)>0,(R25-S25),0) -> 336 | U25: 4169 | V25: =T25*U25 -> 1400784 | W25: Biên
A26: 29 | B26: Nhà sách BK | C26: Nhà xuất bản BK | D26: Lô 2,3,4 tầng 1-A17 | E26: 38684569 | F26: Hoàng Tuấn Bằng | G26: 0915805666 | H26: A17 | J26: 0566 | K26: 3 pha | L26: Tủ ĐN1 | M26: B1 | N26: 18 | O26: 317660 | P26: 316439 | Q26: 1 | R26: =(O26-P26)*Q26 -> 1221 | S26: 0 | T26: =IF((R26-S26)>0,(R26-S26),0) -> 1221 | U26: 4169 | V26: =T26*U26 -> 5090349 | W26: Đông
A27: 30 | B27: Nhà sách BK | C27: Nhà xuất bản BK | D27: Lô 1, tầng 1- A17 | E27: 36230568 | F27: Hoàng Tuấn Bằng | G27: 0915805666 | H27: A17 | J27: 5125 | K27: 1 pha | L27: Tủ ĐN1 | M27: B1 | N27: 18 | O27: 33796 | P27: 33002 | Q27: 1 | R27: =(O27-P27)*Q27 -> 794 | S27: 0 | T27: =IF((R27-S27)>0,(R27-S27),0) -> 794 | U27: 4169 | V27: =T27*U27 -> 3310186 | W27: Đông
A28: 31 | B28: Nhà xuất bản BK | C28: Nhà xuất bản BK | D28: Nhà E | E28: 38684569 | F28: Chị Liễu | H28: A17 | J28: 0322 | K28: 3 pha | L28: Tầng 3 | M28: THCK | N28: 19 | O28: 143497 | P28: 143174 | Q28: 1 | R28: =(O28-P28)*Q28 -> 323 | S28: 0 | T28: =IF((R28-S28)>0,(R28-S28),0) -> 323 | U28: 4169 | V28: =T28*U28 -> 1346587 | W28: Đông
A29: 32 | B29: Bưu điện BK | C29: Bưu điện BK | D29: Lô 12, tầng 1- A17 | E29: 0834214946 | F29: Ngọc | G29: 0834214946 | H29: A17 | J29: 8820 | K29: 1 pha | L29: Tủ ĐN2 | M29: B1 | N29: 20 | O29: 89688 | P29: 89562 | Q29: 1 | R29: =(O29-P29)*Q29 -> 126 | S29: 0 | T29: =IF((R29-S29)>0,(R29-S29),0) -> 126 | U29: 4169 | V29: =T29*U29 -> 525294 | W29: Đông
A30: 33 | B30: Siêu thị MINI BK | C30: HĐKT | D30: Lô 11, tầng 1- A17 | F30: Đỗ Đ.Tâm (Q.Anh) | G30: 0976596779 | H30: A17 | J30: 9838 | K30: 3 pha | L30: Tủ ĐN2 | M30: B1 | N30: 20 | O30: 125079 | P30: 122675 | Q30: 1 | R30: =(O30-P30)*Q30 -> 2404 | S30: 0 | T30: =IF((R30-S30)>0,(R30-S30),0) -> 2404 | U30: 4169 | V30: =T30*U30 -> 10022276 | W30: Đông
A31: 34 | B31: Bún cá Anh Sơn | C31: HĐKT | D31: Lô 10, tầng 1-A17 | F31: Anh Sơn | G31: 0936865486 | H31: A17 | J31: 1735 | K31: 3 pha | L31: Tủ ĐN2 | M31: B1 | N31: 21 | O31: 159004 | P31: 157022 | Q31: 1 | R31: =(O31-P31)*Q31 -> 1982 | S31: 0 | T31: =IF((R31-S31)>0,(R31-S31),0) -> 1982 | U31: 4169 | V31: =T31*U31 -> 8262958 | W31: Đông
A32: 35 | B32: Kiot hàng ăn - A Bình A17 | C32: HĐKT | D32: Lô 9, tầng 1 A17 | E32: 912212968 | F32: Nguyễn Thái Bình | G32: 912212968 | H32: A17 | J32: 1324 | K32: 3 pha | L32: Tủ ĐN2 | M32: ĐCĐT | N32: 19 | O32: 113371 | P32: 111552 | Q32: 1 | R32: =(O32-P32)*Q32 -> 1819 | S32: 0 | T32: =IF((R32-S32)>0,(R32-S32),0) -> 1819 | U32: 4169 | V32: =T32*U32 -> 7583411 | W32: Đông
A33: 36 | B33: Chị Duyên - photocopy | C33: HĐKT | D33: Cầu thang TC | F33: Hoàng thị Thanh Duyên | G33: 0949318686 | H33: TC | J33: 2184 | K33: 1 pha | L33: T1 TC | M33: THCK | N33: 22 | O33: 32728 | P33: 32347 | Q33: 1 | R33: =(O33-P33)*Q33 -> 381 | S33: 0 | T33: =IF((R33-S33)>0,(R33-S33),0) -> 381 | U33: 4169 | V33: =T33*U33 -> 1588389 | W33: Sơn
A34: 40 | B34: Duy Anh - photocopy | C34: HĐKT | D34: Cổng Bể bơi | F34: Duy Anh (Thu D8) | G34: 0942567886 | H34: Bể bơi | J34: 3218 | K34: 1 pha | L34: Tường ngoài | M34: B1 | N34: 23 | O34: 16492 | P34: 16026 | Q34: 1 | R34: =(O34-P34)*Q34 -> 466 | S34: 0 | T34: =IF((R34-S34)>0,(R34-S34),0) -> 466 | U34: 4169 | V34: =T34*U34 -> 1942754 | W34: Sơn
A35: 41 | B35: Nguyễn Thu Trang -Photocopy | C35: HĐKT | D35: Tầng 1 - D3 | E35: 0359933033 | F35: Nguyễn Thu Trang | G35: 0986675792 | H35: D3 | J35: 9876 | K35: 1 pha | L35: T1 D3 | M35: ĐLK | N35: 27 | O35: 60251 | P35: 59995 | Q35: 1 | R35: =(O35-P35)*Q35 -> 256 | S35: 0 | T35: =IF((R35-S35)>0,(R35-S35),0) -> 256 | U35: 4169 | V35: =T35*U35 -> 1067264 | W35: Hoàng
A36: 42 | B36: Công ty TNHH Thương mại HTP Photocopy | C36: HĐKT | D36: Tầng 1 - D3 | E36: 38694529 | F36: Anh Tuấn | G36: 0393953999 | H36: D3 | J36: 9903 | K36: 1 pha | L36: T1 D3 | M36: ĐLK | N36: 27 | O36: 20001 | P36: 19811 | Q36: 1 | R36: =(O36-P36)*Q36 -> 190 | S36: 0 | T36: =IF((R36-S36)>0,(R36-S36),0) -> 190 | U36: 4169 | V36: =T36*U36 -> 792110 | W36: Hoàng
A37: 43 | B37: Ông Nam - Photocopy | C37: HĐKT | D37: Tầng 1 - D5 | E37: 38692116 | F37: Ông Nam | G37: 0912372528 | H37: D5 | J37: 6203 | K37: 1 pha | L37: T1 D5 | M37: ĐLK | N37: 23 | O37: 16985 | P37: 16902 | Q37: 1 | R37: =(O37-P37)*Q37 -> 83 | S37: 0 | T37: =IF((R37-S37)>0,(R37-S37),0) -> 83 | U37: 4169 | V37: =T37*U37 -> 346027 | W37: Hoàng
A38: 44 | B38: Chị Phượng -Photocopy | C38: HĐKT | D38: Tầng 1 - D9 | F38: Nguyễn Thị Phượng | G38: 0942373388 | H38: D9 | J38: 9682 | K38: 1 pha | L38: T1 D9 | M38: ĐLK | N38: 29 | O38: 298 | P38: 172 | Q38: 1 | R38: =(O38-P38)*Q38 -> 126 | S38: 0 | T38: =IF((R38-S38)>0,(R38-S38),0) -> 126 | U38: 4169 | V38: =T38*U38 -> 525294 | W38: Hoàng
A39: 45 | B39: Chị Tình -Photocopy | C39: HĐKT | D39: Tầng 1 - D9 | F39: Võ Thị Tĩnh | G39: 0393245710 | H39: D9 | J39: 4881 | K39: 1 pha | L39: Tủ tổng KCN | M39: ĐLK | N39: 29 | O39: 67345 | P39: 67058 | Q39: 1 | R39: =(O39-P39)*Q39 -> 287 | S39: 0 | T39: =IF((R39-S39)>0,(R39-S39),0) -> 287 | U39: 4169 | V39: =T39*U39 -> 1196503 | W39: Hoàng
A40: 46 | B40: ĐH phòng đọc Thư viện TQB | D40: 111A | F40: Chị Quyên | G40: 0944838353 | H40: TVĐT | J40: 2172 | K40: 3 pha | L40: TV 1C | M40: TVĐT | N40: 30 | O40: 53319 | P40: 53260 | Q40: 1 | R40: =(O40-P40)*Q40 -> 59 | S40: 0 | T40: =IF((R40-S40)>0,(R40-S40),0) -> 59 | U40: 3505 | V40: =T40*U40 -> 206795 | W40: Hoàng
A41: 48 | B41: TT kỹ thuật số Pháp ngữ CNF (AUF) | D41: 227 TV TQB | F41: A Lâm | G41: 0902171933 | H41: TVĐT | J41: 0804 | K41: 1 pha | L41: TV 1D | M41: TVĐT | N41: 31 | O41: 8212 | P41: 7991 | Q41: 1 | R41: =(O41-P41)*Q41 -> 221 | S41: 0 | T41: =IF((R41-S41)>0,(R41-S41),0) -> 221 | U41: 3505 | V41: =T41*U41 -> 774605 | W41: Hoàng
...

Sheet Mẫu phiếu thông báo
A1: ĐẠI HỌC BÁCH KHOA HÀ NỘI | F1: PHIẾU THÔNG BÁO ĐIỆN TIÊU THỤ
A2: BAN CƠ SỞ VẬT CHẤT | F2: Tháng 3 năm 2025
I4: =CONCATENATE("Số phiếu: ",VLOOKUP(I6,Data!A:W,1,0)) -> Số phiếu: 206
A5: =CONCATENATE("Kính gửi: ",VLOOKUP(I6,Data!A:W,2,0)) -> Kính gửi: Công ty Viettel - Cột D8
I6: ='In phieu thu'!C6 -> 206
A7: =CONCATENATE("Địa chỉ hộ tiêu thụ: ",VLOOKUP(I6,Data!A:W,4,0),".") -> Địa chỉ hộ tiêu thụ: BTS tầng mái nhà D8. | I7: =CONCATENATE("Điện thoại: ",VLOOKUP(I6,Data!A:W,5,0),".") -> Điện thoại: .
A8: =CONCATENATE("Đại diện: ",VLOOKUP(I6,Data!A:W,6,0),".") -> Đại diện: Phạm Văn Cương. | I8: =CONCATENATE("Điện thoại: ",VLOOKUP(I6,Data!A:W,7,0),".") -> Điện thoại: 0975715666.
A10: STT | B10: Chỉ số mới | C10: Chỉ số cũ | D10: Hệ số | E10: Điện năng tiêu thụ (kWh) | F10: Bao cấp (kWh) | G10: Đơn giá (VNĐ) | H10: Thành tiền (VNĐ) | I10: =CONCATENATE("Số công tơ: ",VLOOKUP(I6,Data!A:W,10,0),".") -> Số công tơ: 3749.
A13: 1 | B13: =VLOOKUP(I6,Data!A:W,15,0) -> 10975 | C13: =VLOOKUP(I6,Data!A:W,16,0) -> 10975 | D13: =VLOOKUP(I6,Data!A:W,17,0) -> 1 | E13: =(B13-C13)*D13 -> 0 | F13: =VLOOKUP(I6,Data!A:W,19,0) -> 0 | G13: =VLOOKUP(I6,Data!A:W,21,0) -> 4169 | H13: =IF((E13-F13)>0,(E13-F13)*G13,0) -> 0 | I13: =CONCATENATE("Vị trí đặt: ",VLOOKUP(I6,Data!A:W,12,0),".") -> Vị trí đặt: Tầng 11.
I15: =CONCATENATE("TBA: ",VLOOKUP(I6,Data!A:W,13,0),".") -> TBA: BK2.
I16: =CONCATENATE("Mã sổ: ",VLOOKUP(I6,Data!A:W,8,0),".") -> Mã sổ: D8.
I17: =CONCATENATE("Trang: ",VLOOKUP(I6,Data!A:W,9,0),".") -> Trang: .
G18: Tổng cộng: | H18: =SUM(H13:H17) -> 0 | I18: Ban Cơ sở vật chất
A19: =CONCATENATE("Bằng chữ: ",doi_font(doichu(H18)),"./.") -> Bằng chữ: Không đồng./. | I19: ĐT: 024 3 868 1954
H21: Hà Nội, ngày 18 tháng 4 năm 2025
A22: BAN CƠ SỞ VẬT CHẤT | H22: NGƯỜI LẬP PHIẾU
H27: Hồ Thành Long

Sheet Phiếu thông báo
A1: ĐẠI HỌC BÁCH KHOA HÀ NỘI | F1: PHIẾU THÔNG BÁO ĐIỆN TIÊU THỤ
A2: BAN CƠ SỞ VẬT CHẤT | F2: Tháng 3 năm 2025
I4: Số phiếu: 206
A5: Kính gửi: Phòng GD Viettel - cổng Parabol
I6: 206
A7: Địa chỉ hộ tiêu thụ: Toà nhà N2, KM số 2, Đại lộ Thăng long, phường Mễ trì, quận Nam từ liêm, Thành phố Hà Nội, Việt Nam. | I7: Điện thoại: .
A8: Đại diện: Công ty TNHH MTV dịch vụ và thương mại viettelpost. | I8: Điện thoại: 0963723666.
A10: STT | B10: Chỉ số mới | C10: Chỉ số cũ | D10: Hệ số | E10: Điện năng tiêu thụ (kWh) | F10: Bao cấp (kWh) | G10: Đơn giá (VNĐ) | H10: Thành tiền (VNĐ) | I10: Số công tơ: 13833.
A13: 1 | B13: 65470 | C13: 64262 | D13: 1 | E13: 1208 | F13: 0 | G13: 4169 | H13: 5036152 | I13: Vị trí đặt: PKTĐ D4 T1.
I15: TBA: TVĐT.
I16: Mã sổ: .
I17: Trang: .
G18: Tổng cộng: | H18: 5036152 | I18: Ban Cơ sở vật chất
A19: Bằng chữ: Năm triệu ba mươi sáu ngàn một trăm năm mươi hai đồng ./. | I19: ĐT: 024 3 868 1954
H21: Hà Nội, ngày 18 tháng 4 năm 2025
A22: BAN CƠ SỞ VẬT CHẤT | H22: NGƯỜI LẬP PHIẾU
H27: Hồ Thành Long

Sheet Data
A1: BẢNG TỔNG HỢP HỘ TIÊU THỤ ĐIỆN THÁNG 6 NĂM 2025
A3: STT | B3: Hộ tiêu thụ điện | C3: Đơn vị chủ quản | D3: Địa chỉ hộ tiêu thụ điện | E3: Điện thoại hộ tiêu thụ điện | F3: Đại diện hộ tiêu thụ | G3: Điện thoại người đại diện | H3: Nhà/ Tòa nhà | I3: T | J3: Số công tơ | K3: Loại công tơ | L3: Vị trí đặt công tơ | M3: Trạm biến áp | N3: Trang | O3: Chỉ số mới | P3: Chỉ số cũ | Q3: Hệ số nhân | R3: Tổng điện năng tiêu thụ | S3: Bao cấp | T3: Điện năng tiêu thụ phải trả | U3: Đơn giá trả công ty Điện lực HBT và hao tổn đường dây | V3: Thành tiền | W3: Người thực hiện
A4: -1 | B4: -2 | C4: -3 | D4: -4 | E4: -5 | F4: -6 | G4: -7 | H4: -8 | I4: -9 | J4: -10 | K4: -11 | L4: -12 | M4: -13 | N4: -14 | O4: -15 | P4: -15 | Q4: -17 | R4: -18 | S4: -19 | T4: -20 | U4: -21 | V4: -22 | W4: -23
A5: 1 | B5: Kiot Tea & Coffee KĐ B | C5: HĐKT | D5: Lô 3 KĐB - SVĐ | F5: Nguyễn Phi Trường | G5: 0346413588 | H5: SVĐ | J5: 1711 | K5: 1 pha | L5: KĐ B- SVĐ | M5: VVL | N5: 1 | Q5: 1 | R5: =(O5-P5)*Q5 -> 0 | S5: 0 | T5: =IF((R5-S5)>0,(R5-S5),0) -> 0 | U5: 4169 | V5: =T5*U5 -> 0 | W5: Sơn
A6: 2 | B6: Kiot Trịnh Thị Thu Trang | C6: HĐKT | D6: Lô 13B KĐB - SVĐ | E6: 0359933033 | F6: Trịnh Thị Thu Trang | G6: 0986675792 | H6: SVĐ | J6: 3206 | K6: 1 pha | L6: KĐ B- SVĐ | M6: VVL | N6: 1 | O6: 5814 | P6: 5788 | Q6: 1 | R6: =(O6-P6)*Q6 -> 26 | S6: 0 | T6: =IF((R6-S6)>0,(R6-S6),0) -> 26 | U6: 4169 | V6: =T6*U6 -> 108394 | W6: Sơn
A7: 3 | B7: Anh Toàn - BM Vật liệu điện tử | C7: Viện Vật lý kỹ thuật | D7: Phòng R & D Tầng 1 nhà B | F7: A Toàn | G7: 0912258465 | H7: B | J7: 7771 | K7: 1 pha | L7: Nhà B | M7: VVL | N7: 2 | O7: 28105 | P7: 28105 | Q7: 1 | R7: =(O7-P7)*Q7 -> 0 | S7: 0 | T7: =IF((R7-S7)>0,(R7-S7),0) -> 0 | U7: 3505 | V7: =T7*U7 -> 0 | W7: Đông
A8: 4 | B8: Chị Khánh - Dịch vụ SVĐ | C8: HĐKT | D8: Lô 14, 15 KĐB - SVĐ | F8: Chị Khánh | G8: 0975297996 | H8: SVĐ | J8: 5440 | K8: 3 pha | L8: KĐ B- SVĐ | M8: VVL | N8: 2 | O8: 143496 | P8: 140187 | Q8: 1 | R8: =(O8-P8)*Q8 -> 3309 | S8: 0 | T8: =IF((R8-S8)>0,(R8-S8),0) -> 3309 | U8: 4169 | V8: =T8*U8 -> 13795221 | W8: Sơn
A9: 5 | B9: Kiot Trịnh Thị Thu Trang | C9: HĐKT | D9: Lô 7-13A KĐB - SVĐ | E9: 0359933033 | F9: Trịnh Thị Thu Trang | G9: 0986675792 | H9: SVĐ | J9: 4220 | K9: 3 pha | L9: KĐ B- SVĐ | M9: VVL | N9: 3 | O9: 188215 | P9: 184610 | Q9: 1 | R9: =(O9-P9)*Q9 -> 3605 | S9: 0 | T9: =IF((R9-S9)>0,(R9-S9),0) -> 3605 | U9: 4169 | V9: =T9*U9 -> 15029245 | W9: Sơn
A10: 6 | B10: Kiot nướng KĐ B. Trang | C10: HĐKT | D10: Lô 456 KĐ B SVĐ | E10: 0359933033 | F10: Trịnh Thị Thu Trang | G10: 0986675792 | H10: SVĐ | J10: 8737 | K10: 3 pha | L10: KĐ B- SVĐ | M10: VVL | N10: 3 | O10: 31025 | P10: 29211 | Q10: 1 | R10: =(O10-P10)*Q10 -> 1814 | S10: 0 | T10: =IF((R10-S10)>0,(R10-S10),0) -> 1814 | U10: 4169 | V10: =T10*U10 -> 7562566 | W10: Sơn
A11: 7 | B11: Quán ăn uống giải khát c.Ly | C11: HĐKT | D11: Tầng 1 Số 10 TQB | F11: Nguyễn Hương Ly | G11: 0945656446 | H11: Số 10 TQB | J11: 5089 | K11: 3 pha | L11: Tủ tổng T1 | M11: B1 | N11: 4 | O11: 439092 | P11: 436148 | Q11: 1 | R11: =(O11-P11)*Q11 -> 2944 | S11: 0 | T11: =IF((R11-S11)>0,(R11-S11),0) -> 2944 | U11: 4169 | V11: =T11*U11 -> 12273536 | W11: Đông
A12: 8 | B12: Phòng giao dịch Trung tâm VNPT Hà Nội | C12: HĐKT | D12: Tầng 1 Số 10 TQB | E12: 38240993 | F12: Lê Ngọc Anh | G12: 0918764073 | H12: Số 10 TQB | J12: 2174 | K12: 1 pha | L12: Tầng 1 TTPV | M12: B1 | N12: 5 | O12: 83158 | P12: 82313 | Q12: 1 | R12: =(O12-P12)*Q12 -> 845 | S12: 0 | T12: =IF((R12-S12)>0,(R12-S12),0) -> 845 | U12: 4169 | V12: =T12*U12 -> 3522805 | W12: Đông
A13: 9 | B13: CLB Bi-a Phú Kỳ T2 | C13: HĐKT | D13: Tầng 2 Số 10 TQB | F13: Lan Anh | G13: 0912894948 | H13: Số 10 TQB | J13: 1738 | K13: 1 pha | L13: KTĐ T1 | M13: B1 | N13: 6 | O13: 7342 | P13: 3511 | Q13: 1 | R13: =(O13-P13)*Q13 -> 3831 | S13: 0 | T13: =IF((R13-S13)>0,(R13-S13),0) -> 3831 | U13: 4169 | V13: =T13*U13 -> 15971439 | W13: Đông
A14: 10 | B14: CLB Bi-a Yến T2 | C14: HĐKT | D14: Tầng 2 Số 10 TQB | F14: Trịnh Thị Yến | G14: 0888261868 | H14: Số 10 TQB | J14: 2709 | K14: 3 pha | L14: KTĐ T1 | M14: B1 | N14: 6 | O14: 22029 | P14: 19132 | Q14: 1 | R14: =(O14-P14)*Q14 -> 2897 | S14: 0 | T14: =IF((R14-S14)>0,(R14-S14),0) -> 2897 | U14: 4169 | V14: =T14*U14 -> 12077593 | W14: Đông
A15: 11 | B15: Siêu thị Nam Phong | C15: HĐKT | D15: Tầng 1 Số 10 TQB | F15: Nguyễn Triều Phong | G15: 0944289288 | H15: Số 10 TQB | J15: 3448 | K15: 3 pha | L15: Tầng 1 TTPV | M15: B1 | N15: 6 | O15: 485846 | P15: 480771 | Q15: 1 | R15: =(O15-P15)*Q15 -> 5075 | S15: 0 | T15: =IF((R15-S15)>0,(R15-S15),0) -> 5075 | U15: 4169 | V15: =T15*U15 -> 21157675 | W15: Đông
A16: 12 | B16: Lớp học thầy Chung T3 | C16: HĐKT | D16: Tầng 3 Số 10 TQB | F16: Nguyễn Thị Đào | G16: 0972261616 | H16: Số 10 TQB | J16: 2028 | K16: 1 pha | L16: Tầng 3 TTPV | M16: B1 | N16: 7 | O16: 15509 | P16: 13898 | Q16: 1 | R16: =(O16-P16)*Q16 -> 1611 | S16: 0 | T16: =IF((R16-S16)>0,(R16-S16),0) -> 1611 | U16: 4169 | V16: =T16*U16 -> 6716259 | W16: Đông
A17: 13 | B17: Văn phòng thầy Chung | C17: HĐKT | D17: Tầng 4 Số 10 TQB | E17: 0972261616 | F17: Nguyễn Thị Đào | G17: 0972261616 | H17: Số 10 TQB | J17: 9307 | K17: 3 pha | L17: Tầng 1 TTPV | M17: B1 | N17: 8 | O17: 109970 | P17: 105798 | Q17: 1 | R17: =(O17-P17)*Q17 -> 4172 | S17: 0 | T17: =IF((R17-S17)>0,(R17-S17),0) -> 4172 | U17: 4169 | V17: =T17*U17 -> 17393068 | W17: Đông
A18: 14 | B18: Vật lý siêu nhẩm tầng 3 | C18: HĐKT | D18: Tầng 3 Số 10 TQB | F18: Trần Quang Quý | G18: 0977340326 | H18: Số 10 TQB | J18: 8259 | K18: 1 pha | L18: Tầng 1 | M18: B1 | N18: 8 | O18: 12634 | P18: 10219 | Q18: 1 | R18: =(O18-P18)*Q18 -> 2415 | S18: 0 | T18: =IF((R18-S18)>0,(R18-S18),0) -> 2415 | U18: 4169 | V18: =T18*U18 -> 10068135 | W18: Đông
A19: 15 | B19: CLB Bi-a coffee tầng 3 | C19: HĐKT | D19: Tầng 3 Số 10 TQB | F19: Thu Hương | G19: 0912567686 | H19: Số 10 TQB | J19: 7671 | K19: 3 pha | L19: Tầng 3 | M19: B1 | N19: 9 | O19: 347723 | P19: 342391 | Q19: 1 | R19: =(O19-P19)*Q19 -> 5332 | S19: 0 | T19: =IF((R19-S19)>0,(R19-S19),0) -> 5332 | U19: 4169 | V19: =T19*U19 -> 22229108 | W19: Đông
A20: 16 | B20: Công ty CPXD Hoàng Hà | C20: HĐKT | D20: Dịch vụ trông xe - 10A TQB | E20: 0903251444 | F20: Chị Hoa | G20: 0903251444 | H20: Số 10 TQB | J20: 60755 | K20: 3 pha | L20: 10A TQB | M20: B1 | N20: 9 | O20: 198968 | P20: 195768 | Q20: 1 | R20: =(O20-P20)*Q20 -> 3200 | S20: 0 | T20: =IF((R20-S20)>0,(R20-S20),0) -> 3200 | U20: 4169 | V20: =T20*U20 -> 13340800 | W20: Đông
A21: 17 | B21: Kiot chị Hiền cổng TT Y tế | C21: HĐKT | D21: Số 5 TQB | E21: 0978819260 | F21: Chị Hiền | G21: 0915023999 | J21: 1778 | K21: 1 pha | L21: Số 5 TQB | M21: KTX | N21: 10 | O21: 89343 | P21: 88393 | Q21: 1 | R21: =(O21-P21)*Q21 -> 950 | S21: 0 | T21: =IF((R21-S21)>0,(R21-S21),0) -> 950 | U21: 4169 | V21: =T21*U21 -> 3960550 | W21: Đông
A22: 18 | B22: Công ty CP XD Hoàng Hà- VP | C22: HĐKT | D22: Sau nhà A15 TQB - Văn phòng | E22: 0903251444 | F22: Chị Hoa | G22: 0903251444 | H22: A15 | J22: 4936 | K22: 3 pha | L22: Cửa ngoài VP | M22: B1 | N22: 9 | O22: 32418 | P22: 32209 | Q22: 1 | R22: =(O22-P22)*Q22 -> 209 | S22: 0 | T22: =IF((R22-S22)>0,(R22-S22),0) -> 209 | U22: 4169 | V22: =T22*U22 -> 871321 | W22: Đông
A23: 19 | B23: Công ty CP Công nghệ cao GENE Việt | C23: Công ty CP Công nghệ cao GENE Việt | D23: Tầng 11 nhà B1 | E23: 0243.7379150 | F23: Lương Thị Minh Ngoc | G23: 0977295439 | H23: B1 | J23: 1478 | K23: 3 pha | L23: KTĐ T11 | M23: B1 | N23: 11 | O23: 304740 | P23: 301434 | Q23: 1 | R23: =(O23-P23)*Q23 -> 3306 | S23: 0 | T23: =IF((R23-S23)>0,(R23-S23),0) -> 3306 | U23: 4169 | V23: =T23*U23 -> 13782714 | W23: Đông
A24: 20 | B24: Cửa hàng Highlands BK | C24: Công ty CP dịch vụ và cà phê Cao Nguyên | D24: Cửa hàng Highlands B1-TĐN | E24: 0988051418 | F24: Trịnh Thị My | G24: 0948742589 | H24: B1 | J24: 90445 | K24: 3 pha | L24: KTĐ T1 | M24: B1 | N24: 12 | O24: 493925 | P24: 481603 | Q24: 1 | R24: =(O24-P24)*Q24 -> 12322 | S24: 0 | T24: =IF((R24-S24)>0,(R24-S24),0) -> 12322 | U24: 4169 | V24: =T24*U24 -> 51370418 | W24: Đông
A25: 21 | B25: Nhà sách ADC Trần Đại Nghĩa | D25: Nhà sách B1- TĐN | F25: A Quang | G25: 0975744134 | J25: 3307 | K25: 3 pha | L25: KTĐ T1 | M25: B1 | N25: 12 | O25: 79570 | P25: 74040 | Q25: 1 | R25: =(O25-P25)*Q25 -> 5530 | S25: 0 | T25: =IF((R25-S25)>0,(R25-S25),0) -> 5530 | U25: 4169 | V25: =T25*U25 -> 23054570 | W25: Sơn
A26: 22 | B26: Khoa Việt Nam học và Tiếng việt (t thụ) | C26: Trường ĐH KHXH và NV | D26: B7 BIS phố TĐN | E26: 38694323 | F26: Lê Thị Thanh Tâm | G26: 0982886906 | H26: B7 BIS | J26: 9094, 4383 | K26: 3 pha | L26: KTĐ T1 | M26: ĐCĐT | N26: 12 | O26: 4438 | P26: 0 | Q26: 1 | R26: =(O26-P26)*Q26 -> 4438 | S26: 0 | T26: =IF((R26-S26)>0,(R26-S26),0) -> 4438 | U26: 4169 | V26: =T26*U26 -> 18502022 | W26: Biên
A27: 23 | B27: Nhà ăn T3-D2A | C27: Nhà ăn T3-D2A | D27: Tầng 3 - D2A | E27: 0982199862 | F27: A Tiến | G27: 0989483276 | H27: D2A | J27: 9045 | K27: 3 pha | L27: Tầng 1 D2A | M27: TVĐT | N27: 13 | O27: 201790 | P27: 198973 | Q27: 1 | R27: =(O27-P27)*Q27 -> 2817 | S27: 0 | T27: =IF((R27-S27)>0,(R27-S27),0) -> 2817 | U27: 4169 | V27: =T27*U27 -> 11744073 | W27: Sơn
A28: 24 | B28: TT Công nghệ Polyme Compozit và giấy | C28: Trường Vật liệu | D28: Nhà D2B | E28: 38692731 | F28: Nguyễn Thanh Liêm | G28: 0913219791 | H28: D2B | J28: 3399 | K28: 3 pha | L28: Tủ tổng | M28: BK3B | N28: 13 | O28: 11565 | P28: 11478 | Q28: 80 | R28: =(O28-P28)*Q28 -> 6960 | S28: 0 | T28: =IF((R28-S28)>0,(R28-S28),0) -> 6960 | U28: 3505 | V28: =T28*U28 -> 24394800 | W28: Sơn
A29: 25 | B29: Văn phòng cựu sinh viên | D29: D2D | F29: A Nghĩa | G29: 0943751976 | H29: D2D | J29: 7828 | K29: 3 pha | L29: Tầng 1 D2D | M29: BK3B | N29: 14 | O29: 263254 | P29: 259479 | Q29: 1 | R29: =(O29-P29)*Q29 -> 3775 | S29: 0 | T29: =IF((R29-S29)>0,(R29-S29),0) -> 3775 | U29: 3505 | V29: =T29*U29 -> 13231375 | W29: Sơn
A30: 26 | B30: Tạ Thanh Hằng - Photocopy | C30: HĐKT | D30: Nhà D6 | F30: Tạ Thanh Hằng | G30: 0819906149 | H30: D6 | J30: 3842 | K30: 1 pha | L30: T1 D6 | M30: TVĐT | N30: 14 | O30: 45965 | P30: 45614 | Q30: 1 | R30: =(O30-P30)*Q30 -> 351 | S30: 0 | T30: =IF((R30-S30)>0,(R30-S30),0) -> 351 | U30: 4169 | V30: =T30*U30 -> 1463319 | W30: Sơn
A31: 27 | B31: Nhà sách BK | C31: Nhà xuất bản BK | D31: Lô 2,3,4 tầng 1-A17 | E31: 38684569 | F31: Hoàng Tuấn Bằng | G31: 0915805666 | H31: A17 | J31: 0566 | K31: 3 pha | L31: Tủ ĐN1 | M31: B1 | N31: 15 | O31: 327826 | P31: 322893 | Q31: 1 | R31: =(O31-P31)*Q31 -> 4933 | S31: 0 | T31: =IF((R31-S31)>0,(R31-S31),0) -> 4933 | U31: 4169 | V31: =T31*U31 -> 20565677 | W31: Biên
A32: 28 | B32: Nhà sách BK | C32: Nhà xuất bản BK | D32: Lô 1, tầng 1- A17 | E32: 36230568 | F32: Hoàng Tuấn Bằng | G32: 0915805666 | H32: A17 | J32: 5125 | K32: 1 pha | L32: Tủ ĐN1 | M32: B1 | N32: 15 | O32: 37244 | P32: 35879 | Q32: 1 | R32: =(O32-P32)*Q32 -> 1365 | S32: 0 | T32: =IF((R32-S32)>0,(R32-S32),0) -> 1365 | U32: 4169 | V32: =T32*U32 -> 5690685 | W32: Biên
A33: 29 | B33: Nhà xuất bản BK | C33: Nhà xuất bản BK | D33: Nhà E | E33: 38684569 | F33: Chị Liễu | H33: A17 | J33: 0322 | K33: 3 pha | L33: Tầng 3 | M33: THCK | N33: 16 | O33: 145582 | P33: 144506 | Q33: 1 | R33: =(O33-P33)*Q33 -> 1076 | S33: 0 | T33: =IF((R33-S33)>0,(R33-S33),0) -> 1076 | U33: 4169 | V33: =T33*U33 -> 4485844 | W33: Biên
A34: 30 | B34: Bưu điện BK | C34: Bưu điện BK | D34: Lô 12, tầng 1- A17 | E34: 0834214946 | F34: Ngọc | G34: 0834214946 | H34: A17 | J34: 8820 | K34: 1 pha | L34: Tủ ĐN2 | M34: B1 | N34: 16 | O34: 90671 | P34: 90168 | Q34: 1 | R34: =(O34-P34)*Q34 -> 503 | S34: 0 | T34: =IF((R34-S34)>0,(R34-S34),0) -> 503 | U34: 4169 | V34: =T34*U34 -> 2097007 | W34: Biên
A35: 31 | B35: Siêu thị MINI BK | C35: HĐKT | D35: Lô 11, tầng 1- A17 | F35: Đỗ Đ.Tâm (Q.Anh) | G35: 0976596779 | H35: A17 | J35: 9838 | K35: 3 pha | L35: Tủ ĐN2 | M35: B1 | N35: 17 | O35: 131554 | P35: 129256 | Q35: 1 | R35: =(O35-P35)*Q35 -> 2298 | S35: 0 | T35: =IF((R35-S35)>0,(R35-S35),0) -> 2298 | U35: 4169 | V35: =T35*U35 -> 9580362 | W35: Biên
A36: 32 | B36: Bún cá Anh Sơn | C36: HĐKT | D36: Lô 10, tầng 1-A17 | F36: Anh Sơn | G36: 0936865486 | H36: A17 | J36: 1735 | K36: 3 pha | L36: Tủ ĐN2 | M36: B1 | N36: 17 | O36: 166292 | P36: 163786 | Q36: 1 | R36: =(O36-P36)*Q36 -> 2506 | S36: 0 | T36: =IF((R36-S36)>0,(R36-S36),0) -> 2506 | U36: 4169 | V36: =T36*U36 -> 10447514 | W36: Biên
A37: 33 | B37: Kiot hàng ăn - A Bình A17 | C37: HĐKT | D37: Lô 9, tầng 1 A17 | E37: 912212968 | F37: Nguyễn Thái Bình | G37: 912212968 | H37: A17 | J37: 1324 | K37: 3 pha | L37: Tủ ĐN2 | M37: ĐCĐT | N37: 18 | O37: 120940 | P37: 117880 | Q37: 1 | R37: =(O37-P37)*Q37 -> 3060 | S37: 0 | T37: =IF((R37-S37)>0,(R37-S37),0) -> 3060 | U37: 4169 | V37: =T37*U37 -> 12757140 | W37: Biên
A38: 34 | B38: Chị Duyên - photocopy | C38: HĐKT | D38: Cầu thang TC | F38: Hoàng thị Thanh Duyên | G38: 0949318686 | H38: TC | J38: 2184 | K38: 1 pha | L38: T1 TC | M38: THCK | N38: 18 | O38: 33678 | P38: 33678 | Q38: 1 | R38: =(O38-P38)*Q38 -> 0 | S38: 0 | T38: =IF((R38-S38)>0,(R38-S38),0) -> 0 | U38: 4169 | V38: =T38*U38 -> 0 | W38: Đông
A39: 35 | B39: Xưởng in ngõ 40 | C39: Trường Vật liệu | D39: Ngõ 40 Tạ Quang Bửu | F39: Anh Hưng | G39: 0913525259 | J39: 7782 | K39: 3 pha | L39: T2 TC | M39: THCK | N39: 19 | O39: 174029 | P39: 174029 | Q39: 1 | R39: =(O39-P39)*Q39 -> 0 | S39: 0 | T39: =IF((R39-S39)>0,(R39-S39),0) -> 0 | U39: 3505 | V39: =T39*U39 -> 0 | W39: Sơn
A40: 36 | B40: Công ty CP đầu tư dịch vụ Tân Hoàng Gia (Bể bơi BK) | C40: HĐKT | D40: Bể bơi BK | F40: A Thọ | G40: 0915343555 | H40: Bể bơi | J40: 7041 | K40: 3 pha | L40: T1 cầu thang | M40: B1 | N40: 19 | O40: 575714 | P40: 572824 | Q40: 1 | R40: =(O40-P40)*Q40 -> 2890 | S40: 0 | T40: =IF((R40-S40)>0,(R40-S40),0) -> 2890 | U40: 4169 | V40: =T40*U40 -> 12048410 | W40: Đông
A41: 37 | B41: Công ty CP đầu tư dịch vụ Tân Hoàng Gia (Bể bơi BK) | C41: HĐKT | D41: Bể bơi BK | F41: A Thọ | G41: 0915343555 | H41: Bể bơi | J41: 7041 | K41: 3 pha | L41: T1 cầu thang | M41: B1 | N41: 20 | O41: 578604 | P41: 575714 | Q41: 1 | R41: =(O41-P41)*Q41 -> 2890 | S41: 0 | T41: =IF((R41-S41)>0,(R41-S41),0) -> 2890 | U41: 3505 | V41: =T41*U41 -> 10129450 | W41: Đông
...

Sheet Ban  in so
A1: BẢNG TỔNG HỢP HỘ TIÊU THỤ ĐIỆN THÁNG 01 NĂM 2020
A3: STT | B3: Hộ tiêu thụ điện | C3: Đơn vị chủ quản | D3: Địa chỉ hộ tiêu thụ điện | E3: Điện thoại hộ tiêu thụ điện | F3: Đại diện hộ tiêu thụ | G3: Điện thoại người đại diện | H3: Mã quyển | I3: Trang | J3: Số công tơ | K3: Loại công tơ | L3: Vị trí đặt công tơ | M3: Trạm biến áp | N3: HSN | O3: CSM | P3: CSC
A4: 1 | B4: Cty CPĐT triển khai Dịch vụ Công nghệ thông tin & VT Bách Khoa Hà Nội | C4: Cty CPĐT triển khai Dịch vụ Công nghệ thông tin & VT Bách Khoa Hà Nội | D4: Phòng 501, 502 - D5 | E4: 36230870 | F4: Nguyễn Ngọc Tuấn | G4: 0973253788 | J4: 3564 | K4: 1 pha | L4: Tầng 5 D5 | M4: ĐLK | N4: 1 | O4: 48551 | P4: 48551
A5: 2 | B5: Cty CPĐT triển khai Dịch vụ Công nghệ thông tin & VT Bách Khoa Hà Nội | C5: Cty CPĐT triển khai Dịch vụ Công nghệ thông tin & VT Bách Khoa Hà Nội | D5: Phòng 501, 502 - D5 | E5: 36230870 | F5: Nguyễn Ngọc Tuấn | G5: 0973253788 | J5: 8306 | K5: 1 pha | L5: Tầng 5 D5 | M5: ĐLK | N5: 1 | O5: 48198 | P5: 48198
A6: 3 | B6: Cty CPĐT triển khai Dịch vụ Công nghệ thông tin & VT Bách Khoa Hà Nội | C6: Cty CPĐT triển khai Dịch vụ Công nghệ thông tin & VT Bách Khoa Hà Nội | D6: Tầng 5 - ĐN 2 Nhà A17 | E6: 36230870 | F6: Nguyễn Ngọc Tuấn | G6: 0973253788 | J6: 9497 | K6: 3 pha | L6: Tủ ĐN 2 | M6: B1 | N6: 1 | O6: 453883 | P6: 451798
A7: 4 | B7: Ông Dũng - BKHolding | C7: BK Holding | D7: Tầng 2 ĐN2 - Nhà A17 TQB | F7: Nguyễn Trung Dũng | G7: 0913534544 | J7: 5163 | K7: 3 pha | L7: Tủ ĐN2 | M7: B1 | N7: 1 | O7: 99205 | P7: 98401
A8: 5 | B8: Bưu điện Bách Khoa | C8: BK Holding | D8: Phòng 8 Tầng 1 - Nhà A17 TQB | E8: 38680003 | F8: chị Ngọc | G8: 0834214946 | J8: 8820 | K8: 3 pha | L8: Tủ ĐN2 | M8: B1 | N8: 1 | O8: 56199 | P8: 55842
A9: 6 | B9: BK Holding | C9: BK Holding | D9: ĐN 2 Tầng 2- Nhà A17 | F9: Nguyễn Trung Dũng | G9: 0906123357 | J9: 0757 | K9: 3 pha | L9: Tủ cầu thang T2 | M9: B1 | N9: 1 | O9: 61945 | P9: 61623
A10: 7 | B10: BK Holding | C10: BK Holding | D10: Tầng 3 ĐN2 - A17 | E10: 38683713 | F10: Nguyễn Trung Dũng | G10: 0906123357 | J10: 9357 | K10: 3 pha | L10: Tủ ĐN2 | M10: B1 | N10: 1 | O10: 391339 | P10: 389910
A11: 8 | B11: Trường THCS và THPT Tạ Quang Bửu | C11: BK Holding | D11: Nhà C- Viện ĐTLT | F11: Nguyễn Trung Dũng | G11: 0906123357 | J11: 23720 | K11: 3 pha | L11: TBA SVĐ | M11: SVĐ | N11: 100 | O11: 6879 | P11: 6821
A12: 9 | B12: Trường THCS - THPT Tạ Quang Bửu | C12: BK Holding | D12: Nhà C | F12: Nguyễn Trung Dũng | G12: 0906123357 | J12: 0319 | K12: 3 pha | L12: Hầm nhà C | M12: THCK | N12: 1 | O12: 579923 | P12: 579042
A13: 10 | B13: Trường THCS - THPT Tạ Quang Bửu | C13: BK Holding | D13: Nhà C | F13: Nguyễn Trung Dũng | G13: 0906123357 | J13: 2130 | K13: 3 pha | M13: THCK | N13: 1 | O13: 47280 | P13: 47001
A14: 11 | B14: Genetic | C14: BK Holding | D14: Tầng 2 ĐN 1- A17 | E14: 38681016 | F14: Trịnh Hữu Ngọc | G14: 0983366466 | J14: 9277 | K14: 1 pha | L14: Tủ ĐN2 | M14: B1 | N14: 1 | O14: 175447 | P14: 174008
A15: 12 | B15: BK Holding | C15: BK Holding | D15: Tầng 3 ĐN 1- A17 | E15: 38681016 | F15: Trịnh Hữu Ngọc | G15: 0983366466 | J15: 9310 | K15: 3 pha | L15: Tủ ĐN2 | M15: B1 | N15: 1 | O15: 188916 | P15: 186510
A18: 15 | B18: Công ty CP XD Hồng Hà | C18: Công ty CP XD Hồng Hà | D18: Nhà A15 TQB | E18: 0903251444 | F18: chị Hoa | G18: 0903251444 | J18: 4936 | K18: 1 pha | L18: Tủ PP Trạm B1 | M18: B1 | N18: 1 | O18: 24535 | P18: 24117
A19: 16 | B19: Công ty CP XD Hồng Hà | C19: Công ty CP XD Hồng Hà | D19: Dịch vụ trông xe - 10 A TQB | E19: 0903251444 | F19: Chị Hoa | G19: 0903251444 | J19: 60755 | K19: 3 pha | L19: 10A TQB | M19: B1 | N19: 1 | O19: 91236 | P19: 90531
A20: 17 | B20: Công ty CP Thân thiện Môi trường Bách Khoa | C20: Công ty CP Thân thiện Môi trường Bách Khoa | D20: Nhà phụ D6-B | F20: Ông Tạ Văn Sơn | G20: 0903225372 | J20: 6771 | K20: 3 pha | L20: Tủ tổng PTN | M20: TVĐT | N20: 1 | O20: 60870 | P20: 60670
A21: 18 | B21: Công ty TNHH Sản xuất sạch VN | C21: Công ty TNHH sản xuất sạch VN | D21: P 625 - TV TQB | F21: Ông Trần Văn Nhân | G21: 0903444741 | J21: 4 CT loại 226,687,226, 1226 | L21: KTĐ C6 | M21: TVĐT | N21: 1 | O21: 1101 | P21: 946
A22: 19 | B22: Công ty TNHH SX sạch VN | C22: Công ty TNHH sản xuất sạch VN | D22: Tầng 4 - C10 | E22: 38681686 | F22: Ông Trần Văn Nhân | G22: 0903444741 | J22: 2484 | K22: 3 pha | L22: Tầng 4 C10 | M22: BK1 | N22: 1 | O22: 0 | P22: 0
A23: 20 | B23: Công ty Cổ phần Cơ khí chính xác | C23: Công ty Cổ phần Cơ khí chính xác | D23: Xưởng C8b | E23: 38692332 | F23: Nguyễn Chí Hưng | G23: 0974041888 | J23: 7269 | K23: 3 pha | L23: Tủ tổng xưởng | M23: BK1 | N23: 40 | O23: 15724 | P23: 15690
A24: 166 | B24: Công ty Cơ khí chính xác | C24: Viện Cơ khí | F24: Nguyễn Chí Hưng | G24: 0974041888 | J24: 2453 | K24: 3 pha | L24: Trong xưởng | M24: KTX | N24: 1 | P24: 117987
A25: 167 | B25: Công ty Cơ khí chính xác | C25: Viện Cơ khí | F25: Nguyễn Chí Hưng | G25: 0974041888 | J25: 6837 | K25: 3 pha | L25: Tủ tổng A15 | M25: KTX | N25: 1 | P25: 205115
A28: 21 | B28: Anh Tuấn (Công ty TNHH chuyển giao & công nghệ Bách Khoa) | C28: Cty TNHH MTV tư vấn và CGCN BK | D28: Số 5- Ngõ 15 - TQB | E28: 38692384 | F28: Anh Tuấn | G28: 0915629488 | J28: 2278 | K28: 3 pha | L28: Cầu thang | M28: KTX | N28: 1 | P28: 44329
A29: 22 | B29: Khoa Tiếng Việt- ĐHKHXH & NV | C29: ĐH KHXH& NV - Khoa Tiếng Việt | D29: B7 Bis | E29: 38694323 | F29: Ông Nam | G29: 0912482100 | J29: 9094 | K29: 3 pha | L29: Tầng 1- Khoa TV | M29: BK1 | N29: 1 | O29: 2155 | P29: 0
A30: 23 | B30: Phòng giao dịch chi nhánh Hà Thành | C30: Ngân hàng TMCP Đầu tư và Phát triển chi nhánh Hà Thành | D30: Phòng 4 Tầng 1 - Nhà A17 TQB | E30: 38683907 | F30: Nguyễn Thị Đông | G30: 0915344727 | J30: 9278 | K30: 1 pha | L30: Tủ ĐN1 | M30: B1 | N30: 1 | O30: 115119 | P30: 113401
A31: 24 | B31: ATM BIDV chi nhánh Hà Thành | C31: Ngân hàng TMCP Đầu tư và Phát triển chi nhánh Hà Thành | D31: ATM - D3 | E31: 38683907 | F31: Nguyễn Thị Đông | G31: 0915344727 | J31: 4829 | K31: 1 pha | L31: D3 | M31: ĐLK | N31: 1 | O31: 5367 | P31: 4900
A32: 25 | B32: Agribank chi nhánh Thủ Đô | C32: Agribank chi nhánh Thủ Đô | D32: ATM - Cổng bảo vệ C8 | E32: 39447683 | F32: Nguyễn Thùy Nhung | G32: 0987265632 | J32: 6156 | K32: 1 pha | L32: D3 | M32: ĐLK | N32: 1 | O32: 2025 | P32: 1784
A33: 26 | B33: Phòng giao dịch chi nhánh Hai Bà Trưng | C33: Ngân hàng TMCP Công thương Việt Nam- Chi nhánh Hai Bà Trưng | D33: Phòng 5 Tầng 1 - Nhà A17 TQB | J33: 1731 | K33: 1 pha | L33: Tủ ĐN2 | M33: B1 | N33: 1 | O33: 150621 | P33: 149262
A34: 27 | B34: Ngân hàng TMCP Công thương Việt Nam- Chi nhánh Hai Bà Trưng | C34: Ngân hàng TMCP Công thương Việt Nam- Chi nhánh Hai Bà Trưng | D34: ATM - D3 | J34: 50952 | K34: 1 pha | L34: Tổng D3 | M34: ĐLK | N34: 1 | O34: 60926 | P34: 59837
A35: 28 | B35: Ngân hàng VP BANK (thanh lý không dùng nữa) | C35: Ngân hàng VP BANK | D35: ATM - D3 | F35: Tạ Xuân Hiệu | G35: 0982501226 | J35: 2261 | K35: 1 pha | L35: Tổng D3 | M35: ĐLK | N35: 1 | P35: 0
A36: 29 | B36: Nhà xuất bản BK | C36: Nhà xuất bản BK | D36: Nhà E | E36: 38684569 | F36: Phùng Lan Hương | G36: 0905608271 | J36: 0322 | K36: 3 pha | L36: Tầng 3 | M36: THCK | N36: 1 | O36: 108683 | P36: 108344
A37: 30 | B37: A Bằng - Quán tròn | C37: Nhà xuất bản BK | D37: Đường đôi | E37: 38682917 | F37: Hoàng Tuấn Bằng | G37: 0915805666 | J37: 1271 | K37: 1 pha | L37: Nấm tròn đường đôi | M37: BK2 | N37: 1 | O37: 5186 | P37: 5161
A38: 31 | B38: Nhà sách BK | C38: Nhà sách Bách Khoa | D38: Phòng 3 Tầng 1 - Nhà A17 | E38: 38684569 | F38: Hoàng Tuấn Bằng | G38: 0915805666 | J38: 0566 | K38: 1 pha | L38: Tủ ĐN1 | M38: B1 | N38: 1 | O38: 179170 | P38: 178161
A39: 32 | B39: Nhà sách BK | C39: Nhà sách Bách Khoa | D39: Phòng 2 Tầng 1 - Nhà A17 TQB | E39: 36230568 | F39: Hoàng Tuấn Bằng | G39: 0915805666 | J39: 5125 | K39: 1 pha | L39: Tủ ĐN1 | M39: B1 | N39: 1 | O39: 65237 | P39: 64256
A40: 33 | B40: Nhà sách Bách Khoa | C40: Nhà sách Bách Khoa | D40: Nhà sách Bách Khoa | F40: Hoàng Tuấn Bằng | G40: 0915805666 | J40: 0625 | K40: 3 pha | M40: B1 | N40: 1 | O40: 78073 | P40: 78073
A41: 34 | B41: Nhà ăn A 1-5 | C41: Nhà ăn A 1-5 | D41: Nhà A15 TQB | F41: Dương Văn Thế | G41: 0912339926 | J41: 11498 | K41: 3 pha | L41: Tủ tổng A15 | M41: B1 | N41: 1
A42: 35 | B42: Nhà ăn A 1-5 | C42: Nhà ăn A 1-5 | D42: Nhà A15 TQB | F42: Dương Văn Thế | G42: 0912339926 | J42: 23804 | K42: 3 pha | L42: Tủ tổng A15 | M42: KTX | N42: 30 | O42: 3892 | P42: 3867
A43: 36 | B43: Anh Tường | C43: Phòng HCTH | D43: Tổ Ô tô - Ngõ 17 TQB | E43: 38694242 | F43: Nguyễn Văn Tường | G43: 0345419113 | J43: 3113 | K43: 1 pha | L43: Tổ ô tô | M43: KTX | N43: 1 | O43: 10194 | P43: 10057
A44: 37 | B44: Anh Chiến | C44: Phòng HCTH | D44: Tổ Ô tô - Ngõ 17 TQB | E44: 38694242 | F44: Ngô Viết Chiến | G44: 0912460604 | J44: 1780 | K44: 1 pha | L44: Tổ ô tô | M44: KTX | N44: 1 | O44: 1375 | P44: 1375
A45: 38 | B45: Anh Hà | C45: Phòng HCTH | D45: Tổ Ô tô - Ngõ 17 TQB | E45: 0976117610 | F45: Anh Hà | G45: 0976117610 | J45: 9780 | K45: 1 pha | L45: Tổ ô tô | M45: KTX | N45: 1 | O45: 13356 | P45: 13293
...

Sheet Trường Cơ khí
A1: ĐẠI HỌC BÁCH KHOA HÀ NỘI | F1: PHIẾU THÔNG BÁO ĐIỆN TIÊU THỤ
A2: PHÒNG CƠ SỞ VẬT CHẤT | F2: Tháng 6 năm 2023
J4: Số phiếu: 234
A5: Kính gửi: Trường Cơ khí
J6: 234
A7: Địa chỉ hộ tiêu thụ: Trường Cơ khí. | J7: Điện thoại: .
A8: Đại diện: Trường Cơ khí. | J8: Điện thoại: 38696165
A10: STT | B10: Chỉ số mới | C10: Chỉ số cũ | D10: Hệ số | E10: Điện năng tiêu thụ (kWh) | F10: Bao cấp (kWh) | G10: Đơn giá (VNĐ) | H10: Thành tiền (VNĐ) | I10: Tên đơn vị | J10: Địa chỉ
A13: 1 | B13: 1769 | C13: 1768 | D13: 120 | E13: =(B13-C13)*D13 -> 120 | F13: 0 | G13: 3505 | H13: =G13*E13 -> 420600 | I13: TT Kỹ thuật cơ khí | J13: B1
A14: 2 | B14: 62636 | C14: 62393 | D14: 1 | E14: =(B14-C14)*D14 -> 243 | G14: 3505 | H14: =G14*E14 -> 851715 | I14: TT Kỹ thuật cơ khí | J14: B1
A15: 3 | B15: 95475 | C15: 95395 | D15: 1 | E15: =(B15-C15)*D15 -> 80 | G15: 3505 | H15: =G15*E15 -> 280400 | I15: TT Kỹ thuật cơ khí | J15: T - 101 Phòng CNC công nghiệp
A16: 4 | B16: 28589 | C16: 28449 | D16: 1 | E16: =(B16-C16)*D16 -> 140 | G16: 3505 | H16: =G16*E16 -> 490700 | I16: TT Kỹ thuật cơ khí | J16: T - P 107
A17: 5 | B17: 33512 | C17: 33448 | D17: 1 | E17: =(B17-C17)*D17 -> 64 | G17: 3505 | H17: =G17*E17 -> 224320 | I17: TT Kỹ thuật cơ khí | J17: T- Ban Phay bào
A18: 6 | B18: 5204 | C18: 5166 | D18: 1 | E18: =(B18-C18)*D18 -> 38 | G18: 3505 | H18: =G18*E18 -> 133190 | I18: TT Kỹ thuật cơ khí | J18: T- 110A PTN Hàn
A19: 7 | B19: 54663 | C19: 54443 | D19: 1 | E19: =(B19-C19)*D19 -> 220 | G19: 3505 | H19: =G19*E19 -> 771100 | I19: TT Kỹ thuật cơ khí | J19: T- PTN Hàn 110
A20: 8 | B20: 13909 | C20: 13892 | D20: 1 | E20: =(B20-C20)*D20 -> 17 | G20: 3505 | H20: =G20*E20 -> 59585 | I20: TT Kỹ thuật cơ khí | J20: T-101,102, nhà mái tôn
A21: 9 | B21: 10919 | C21: 10903 | D21: 1 | E21: =(B21-C21)*D21 -> 16 | G21: 3505 | H21: =G21*E21 -> 56080 | I21: TT Kỹ thuật cơ khí | J21: T - 206
A22: 10 | B22: 14847 | C22: 14821 | D22: 1 | E22: =(B22-C22)*D22 -> 26 | G22: 3505 | H22: =G22*E22 -> 91130 | I22: TT Kỹ thuật cơ khí | J22: T - 207
A23: 11 | B23: 15180 | C23: 15020 | D23: 1 | E23: =(B23-C23)*D23 -> 160 | G23: 3505 | H23: =G23*E23 -> 560800 | I23: TT Kỹ thuật cơ khí - VP | J23: T- 210
A24: 12 | B24: 1923 | C24: 1865 | D24: 1 | E24: =(B24-C24)*D24 -> 58 | G24: 3505 | H24: =G24*E24 -> 203290 | I24: PTN Ô tô ĐN1 | J24: Nhà mái tôn gần hàng rào ĐN1
A25: 13 | B25: 545 | C25: 525 | D25: 30 | E25: =(B25-C25)*D25 -> 600 | G25: 3505 | H25: =G25*E25 -> 2103000 | I25: Phòng TN Đông cơ đốt trong - Ánh sáng | J25: C15
... A35: 23 | B35: 134678 | C35: 134543 | D35: 1 | E35: =(B35-C35)*D35 -> 135 | G35: 3505 | H35: =G35*E35 -> 473175 | I35: PTN Thủy khí | J35: Nhà T-P 109
G36: Tổng cộng: | H36: =SUM(H13:H35) -> 23420410
A37: Bằng chữ: Hai mươi ba triệu, bốn hai mươi nghìn, bốn trăm mười đồng ./.
H39: Hà Nội, ngày 21 tháng 7 năm 2023
A40: PHÒNG CƠ SỞ VẬT CHẤT | H40: NGƯỜI LẬP PHIẾU
H44: Hồ Thành Long

Sheet Trường Điện - Điện tử
A1: ĐẠI HỌC BÁCH KHOA HÀ NỘI | F1: PHIẾU THÔNG BÁO ĐIỆN TIÊU THỤ
A2: PHÒNG CƠ SỞ VẬT CHẤT | F2: Tháng 6 năm 2023
J4: Số phiếu: 234
A5: Kính gửi: Trường Điện - Điện tử
J6: 234
A7: Địa chỉ hộ tiêu thụ: Trường Điện - Điện tử. | J7: Điện thoại: 3869 2242
A8: Đại diện: Trường Điện - Điện tử. | J8: Điện thoại: 3869 6211
A10: STT | B10: Chỉ số mới | C10: Chỉ số cũ | D10: Hệ số | E10: Điện năng tiêu thụ (kWh) | F10: Bao cấp (kWh) | G10: Đơn giá (VNĐ) | H10: Thành tiền (VNĐ) | I10: Tên đơn vị | J10: Địa chỉ
A13: 1 | B13: 250627 | C13: 250602 | D13: 1 | E13: =(B13-C13)*D13 -> 25 | G13: 3505 | H13: =G13*E13 -> 87625 | I13: PTN Vi Mạch 611 - Điện tử Viễn thông | J13: Phòng 611 - TV TQB
A14: 2 | B14: 47726 | C14: 46527 | D14: 1 | E14: =(B14-C14)*D14 -> 1199 | G14: 3505 | H14: =G14*E14 -> 4202495 | I14: PTN Trường Điện - Điện tử | J14: Tầng 4 - Nhà C1B
A15: 3 | B15: 351 | C15: 0 | D15: 1 | E15: =(B15-C15)*D15 -> 351 | G15: 3505 | H15: =G15*E15 -> 1230255 | I15: Các phòng thực hành ĐTVT (đèn, quạt..) t thụ | J15: Nhà T - tầng 3
A16: 4 | B16: 60749 | C16: 60127 | D16: 1 | E16: =(B16-C16)*D16 -> 622 | G16: 3505 | H16: =G16*E16 -> 2180110 | I16: Các phòng thực hành ĐTVT (Bàn thí nghiệm) | J16: Nhà T - tầng 3
A17: 5 | B17: 96156 | C17: 96154 | D17: 1 | E17: =(B17-C17)*D17 -> 2 | G17: 3505 | H17: =G17*E17 -> 7010 | I17: Trung tâm thực hành ĐTVT B4 | J17: Trung tâm thực hành B4 - số 5 TQB
A18: 6 | B18: 932 | C18: 888 | D18: 20 | E18: =(B18-C18)*D18 -> 880 | G18: 3505 | H18: =G18*E18 -> 3084400 | I18: TT Đào tạo thực hành Đ-ĐT. D8 | J18: D8 T8
A19: 7 | B19: 20 | C19: 18 | D19: 20 | E19: =(B19-C19)*D19 -> 40 | G19: 3505 | H19: =G19*E19 -> 140200 | I19: TT Đào tạo thực hành Đ-ĐT. D8 | J19: D8 T8
A20: 8 | B20: 500 | C20: 484 | D20: 20 | E20: =(B20-C20)*D20 -> 320 | G20: 3505 | H20: =G20*E20 -> 1121600 | I20: TT Đào tạo thực hành Đ-ĐT. D8 | J20: D8 T9
A21: 9 | B21: 166 | C21: 162 | D21: 20 | E21: =(B21-C21)*D21 -> 80 | G21: 3505 | H21: =G21*E21 -> 280400 | I21: TT Đào tạo thực hành Đ-ĐT. D8 | J21: D8 T9
A22: 10 | B22: 743 | C22: 698 | D22: 20 | E22: =(B22-C22)*D22 -> 900 | G22: 3505 | H22: =G22*E22 -> 3154500 | I22: TT Đào tạo thực hành Đ-ĐT. D8 | J22: D8 T10
A23: 11 | B23: 320 | C23: 304 | D23: 20 | E23: =(B23-C23)*D23 -> 320 | G23: 3505 | H23: =G23*E23 -> 1121600 | I23: TT Đào tạo thực hành Đ-ĐT. D8 | J23: D8 T10
G24: Tổng cộng: | H24: =SUM(H13:H16) -> 7700485 | J24: Phòng Cơ sở vật chất
A25: Bằng chữ: Ba mươi bốn triệu, sáu trăm ba mươi hai nghìn, ba trăm bốn mươi hai đồng ./. | J25: ĐT: 024 3 868 1954
H27: Hà Nội, ngày 21 tháng 7 năm 2023
A28: PHÒNG CƠ SỞ VẬT CHẤT | H28: NGƯỜI LẬP PHIẾU
H32: Hồ Thành Long

Sheet Trường CNTT 
A1: ĐẠI HỌC BÁCH KHOA HÀ NỘI | F1: PHIẾU THÔNG BÁO ĐIỆN TIÊU THỤ
A2: PHÒNG CƠ SỞ VẬT CHẤT | F2: Tháng 6 năm 2023
J4: Số phiếu: 234
A5: Kính gửi: Trường CNTT & TT
J6: 234
A7: Địa chỉ hộ tiêu thụ: Trường CNTT & TT. | J7: Điện thoại:
A8: Đại diện: Trường CNTT & TT. | J8: Điện thoại: 38 692 463
A10: STT | B10: Chỉ số mới | C10: Chỉ số cũ | D10: Hệ số | E10: Điện năng tiêu thụ (kWh) | F10: Bao cấp (kWh) | G10: Đơn giá (VNĐ) | H10: Thành tiền (VNĐ) | I10: Tên đơn vị | J10: Địa chỉ
A13: 1 | B13: 23883 | C13: 0 | D13: 1 | E13: =(B13-C13)*D13 -> 23883 | F13: 0 | G13: 3354 | H13: =G13*E13 -> 80103582 | I13: Trường CNTT và TT (t thụ) | J13: B1 (Phòng máy, VP trường, VP Khoa, TT, BM)
A14: 2 | B14: 319423 | C14: 312006 | D14: 1 | E14: =(B14-C14)*D14 -> 7417 | G14: 3354 | H14: =G14*E14 -> 24876618 | I14: Trường CNTT và TT (TT máy tính D5) | J14: D5 tầng 3
G15: Tổng cộng: | H15: =SUM(H13:H14) -> 104980200 | J15: Phòng Cơ sở vật chất
A16: Bằng chữ: Ba mươi bốn triệu, sáu trăm ba mươi hai nghìn, ba trăm bốn mươi hai đồng ./. | J16: ĐT: 024 3 868 1954
H18: Hà Nội, ngày 21 tháng 7 năm 2023
A19: PHÒNG CƠ SỞ VẬT CHẤT | H19: NGƯỜI LẬP PHIẾU
H23: Hồ Thành Long

Sheet Trường Hóa & KHSS
A1: ĐẠI HỌC BÁCH KHOA HÀ NỘI | F1: PHIẾU THÔNG BÁO ĐIỆN TIÊU THỤ
A2: PHÒNG CƠ SỞ VẬT CHẤT | F2: Tháng 6 năm 2023
J4: Số phiếu: 234
A5: Kính gửi: Trường Hóa và KHSS
J6: 234
A7: Địa chỉ hộ tiêu thụ: Trường Hóa và KHSS. | J7: Điện thoại: 3868 2470
A8: Đại diện: Trường Hóa và KHSS. | J8: Điện thoại: 3869.2515
A10: STT | B10: Chỉ số mới | C10: Chỉ số cũ | D10: Hệ số | E10: Điện năng tiêu thụ (kWh) | F10: Bao cấp (kWh) | G10: Đơn giá (VNĐ) | H10: Thành tiền (VNĐ) | I10: Tên đơn vị | J10: Địa chỉ
A13: 1 | B13: 10838 | C13: 10805 | D13: 80 | E13: =B13-C13 -> 33 | G13: 3505 | H13: =G13*E13*D13 -> 9253200 | I13: TT Công nghệ Polyme Compozit và giấy | J13: Nhà D2B
A14: 2 | B14: 160828 | C14: 160041 | D14: 1 | E14: =B14-C14 -> 787 | G14: 3505 | H14: =G14*E14*D14 -> 2758435 | I14: Chị Yến -TT Đào tạo & PT Sản phẩm TP | J14: Tầng 1 - B4, ngõ 15 TQB
A15: 3 | B15: 7275 | C15: 7238 | D15: 1 | E15: =B15-C15 -> 37 | G15: 3505 | H15: =G15*E15*D15 -> 129685 | I15: PTN BM Quá trình TBCNTP | J15: Tầng 1 - B4, ngõ 15 TQB
A16: 4 | B16: 11988 | C16: 11930 | D16: 100 | E16: =B16-C16 -> 58 | G16: 3505 | H16: =G16*E16*D16 -> 20329000 | I16: TT R & D sản phẩm TP - TRIC | J16: Tầng 3 Tòa nhà B1
A17: 5 | B17: 219284 | C17: 219274 | D17: 1 | E17: =B17-C17 -> 10 | G17: 3505 | H17: =G17*E17*D17 -> 35050 | I17: Xưởng D6B Viện KHCN MT | J17: D6B
A18: 6 | B18: 89025 | C18: 88857 | D18: 1 | E18: =B18-C18 -> 168 | G18: 3505 | H18: =G18*E18*D18 -> 588840 | I18: KH& CN Môi trường | J18: T3 - C10
A19: 7 | B19: 28593 | C19: 28524 | D19: 1 | E19: =B19-C19 -> 69 | G19: 3505 | H19: =G19*E19*D19 -> 241845 | I19: KH& CN Môi trường | J19: P 403, 406 C10
A20: 8 | B20: 37377 | C20: 36243 | D20: 1 | E20: =B20-C20 -> 1134 | G20: 3505 | H20: =G20*E20*D20 -> 3974670 | I20: NC&PT ứng dụng Hóa chất tự nhiên | J20: T1 - C10
A21: 9 | B21: 2425 | C21: 0 | D21: 1 | E21: =B21-C21 -> 2425 | G21: 3505 | H21: =G21*E21*D21 -> 8499625 | I21: TT Cao su (t thụ) | J21: D7, D2A
G22: Tổng cộng: | H22: =SUM(H13:H13) -> 9253200 | J22: Phòng Cơ sở vật chất
A23: Bằng chữ: Ba mươi bốn triệu, sáu trăm ba mươi hai nghìn, ba trăm bốn mươi hai đồng ./. | J23: ĐT: 024 3 868 1954
H25: Hà Nội, ngày 21 tháng 7 năm 2023
A26: PHÒNG CƠ SỞ VẬT CHẤT | H26: NGƯỜI LẬP PHIẾU
H30: Hồ Thành Long

Sheet Trường Vật liệu
